Workbook
Name Colo: #REF!
Name Data: #REF!
Name Features: #REF!
Name Functional: #REF!
Name General: #REF!
Name intEstimateVolume: 'Demand Requests'!$N$4
Name intEstimateVolume: 'Demand Requests'!$N$4
Name Non_Functional: #REF!
Name Non_Technical: #REF!
Name percPreTargetAdjustment: 'Monthly Recurring Charges'!$AP$3
Name percPreTargetAdjustment: 'Monthly Recurring Charges'!$AP$3
Name Relative: #REF!
Name Technical: #REF!

Sheet introduction
B1: Schedule 5.A (Pricing Sheet) – introduction
B4: This document lists Pricing for the items set out.
B6: Worksheet | C6: Description | D6: Charges
B7: Summary | C7: Overview of the Charges prognosed | D7: Total
B8: Monthly Recurring Charges | C8: Prices that are repetitive, often based on measured volumes | D8: MRC
B9: RU info | C9: Resource Unit measurement and baseline bands | D9: MRC
B10: RU mapping | C10: Show which sections of which service description are covered under which resource units – note that documents other than the referenced service descriptions also contain obligations. | D10: MRC
B11: Devices | C11: Local pricing for laptops, desktops, and printers | D11: MRC
B12: One-time Charges | C12: Prices that are paid once for every execution of an item | D12: OTC
B13: Service Requests | C13: One-time Charges for selected standard changes | D13: OTC
B14: Demand Requests | C14: Hourly Rates for Projects and other work | D14: OTC
B19: Attachment to the: | C19: Schedule 5 (Service Pricing)
B20: of the: | C20: Technology Services
B21: between: | C21: Koninklijke Douwe Egberts B.V.
B22: and: | C22: HCL Technologies B V
B23: Classification: | C23: Confidential Information

Sheet Summary
A1: Schedule 5.A (Pricing Sheet) – Summary
B4: Area | D4: Year 01 | E4: Year 02 | F4: Year 03 | G4: Year 04 | H4: Year 05 | I4: Total | J4: Remarks
B6: Monthly Recurring Charges
C7: Service Integration and Management (SIAM) | D7: ='Monthly Recurring Charges'!AX8 -> 482083.4 | E7: ='Monthly Recurring Charges'!AY8 -> 818164.4 | F7: ='Monthly Recurring Charges'!AZ8 -> 793619.47 | G7: ='Monthly Recurring Charges'!BA8 -> 769810.88 | H7: ='Monthly Recurring Charges'!BB8 -> 746716.56 | I7: =SUM(D7:H7) -> 3610394.7
C8: Service Desk Services (SDS) | D8: ='Monthly Recurring Charges'!AX11 -> 375947.96 | E8: ='Monthly Recurring Charges'!AY11 -> 618702.92 | F8: ='Monthly Recurring Charges'!AZ11 -> 587767.78 | G8: ='Monthly Recurring Charges'!BA11 -> 558379.39 | H8: ='Monthly Recurring Charges'!BB11 -> 530460.42 | I8: =SUM(D8:H8) -> 2671258.5
C9: Workplace Services (WPS) | D9: ='Monthly Recurring Charges'!AX18 -> 1959711.2 | E9: ='Monthly Recurring Charges'!AY18 -> 3225124.7 | F9: ='Monthly Recurring Charges'!AZ18 -> 3027947.7 | G9: ='Monthly Recurring Charges'!BA18 -> 2876550.3 | H9: ='Monthly Recurring Charges'!BB18 -> 2732722.8 | I9: =SUM(D9:H9) -> 13822057
C10: Devices | D10: =Devices!G86 -> 1209499.7 | E10: =Devices!H86 -> 2008751.5 | F10: =Devices!I86 -> 2391385.6 | G10: =Devices!J86 -> 3025907.2 | H10: =Devices!K86 -> 3108123.5 | I10: =SUM(D10:H10) -> 11743668
C11: Cloud and Infrastructure Services (CIS) | D11: ='Monthly Recurring Charges'!AX29 -> 210944.85 | E11: ='Monthly Recurring Charges'!AY29 -> 347154.95 | F11: ='Monthly Recurring Charges'!AZ29 -> 297411.49 | G11: ='Monthly Recurring Charges'!BA29 -> 282540.91 | H11: ='Monthly Recurring Charges'!BB29 -> 268413.87 | I11: =SUM(D11:H11) -> 1406466.1
C12: Operational Technology Services (OTS) | D12: ='Monthly Recurring Charges'!AX39 -> 659134.54 | E12: ='Monthly Recurring Charges'!AY39 -> 1088781.9 | F12: ='Monthly Recurring Charges'!AZ39 -> 1034342.8 | G12: ='Monthly Recurring Charges'!BA39 -> 982625.63 | H12: ='Monthly Recurring Charges'!BB39 -> 933494.34 | I12: =SUM(D12:H12) -> 4698379.1
C13: Security Services (SEC) | D13: ='Monthly Recurring Charges'!AX58 -> 412009.47 | E13: ='Monthly Recurring Charges'!AY58 -> 678049.88 | F13: ='Monthly Recurring Charges'!AZ58 -> 644147.38 | G13: ='Monthly Recurring Charges'!BA58 -> 611940.01 | H13: ='Monthly Recurring Charges'!BB58 -> 581343.01 | I13: =SUM(D13:H13) -> 2927489.8
C14: Options | D14: ='Monthly Recurring Charges'!AX7 -> 125601.37 | E14: ='Monthly Recurring Charges'!AY7 -> 206703.97 | F14: ='Monthly Recurring Charges'!AZ7 -> 244328.92 | G14: ='Monthly Recurring Charges'!BA7 -> 233447.17 | H14: ='Monthly Recurring Charges'!BB7 -> 223109.52 | I14: =SUM(D14:H14) -> 1033190.9
C15: Subtotal | D15: =SUM(D7:D14) -> 5434932.5 | E15: =SUM(E7:E14) -> 8991434.2 | F15: =SUM(F7:F14) -> 9020951.1 | G15: =SUM(G7:G14) -> 9341201.5 | H15: =SUM(H7:H14) -> 9124384 | I15: =SUM(I7:I14) -> 41912903
B17: One-time Charges | I17: =I15+I26 -> 42504341
C18: ='One-time Charges'!B8 -> Transition and Transformation
C19: ='One-time Charges'!C10 -> Transition | D19: ='One-time Charges'!H10 -> 0 | E19: ='One-time Charges'!I10 -> 0 | F19: ='One-time Charges'!J10 -> 0 | G19: ='One-time Charges'!K10 -> 0 | H19: ='One-time Charges'!L10 -> 0 | I19: =SUM(D19:H19) -> 0
C20: ='One-time Charges'!C24 -> Transformation | D20: ='One-time Charges'!H24 -> 0 | E20: ='One-time Charges'!I24 -> 365488.94 | F20: ='One-time Charges'!J24 -> 365488.94 | G20: ='One-time Charges'!K24 -> 365488.94 | H20: ='One-time Charges'!L24 -> 365488.94 | I20: =SUM(D20:H20) -> 1461955.7
C21: ='One-time Charges'!C45 -> Other – In-flight Projects or future Projects | D21: ='One-time Charges'!H45 -> 0 | E21: ='One-time Charges'!I45 -> 131220.05 | F21: ='One-time Charges'!J45 -> 131220.05 | G21: ='One-time Charges'!K45 -> 131220.05 | H21: ='One-time Charges'!L45 -> 454449.46 | I21: =SUM(D21:H21) -> 848109.61
C22: ='One-time Charges'!C51 -> Transfer of Assets | D22: ='One-time Charges'!H51 -> 0 | E22: ='One-time Charges'!I51 -> 0 | F22: ='One-time Charges'!J51 -> 0 | G22: ='One-time Charges'!K51 -> 0 | H22: ='One-time Charges'!L51 -> 0 | I22: =SUM(D22:H22) -> 0
C23: Options | D23: ='One-time Charges'!H9 -> 0 | E23: ='One-time Charges'!I9 -> 0 | F23: ='One-time Charges'!J9 -> 233172.15 | G23: ='One-time Charges'!K9 -> 0 | H23: ='One-time Charges'!L9 -> 0 | I23: =SUM(D23:H23) -> 233172.15
C24: Subtotal | D24: =SUM(D19:D23) -> 0 | E24: =SUM(E19:E23) -> 496708.99 | F24: =SUM(F19:F23) -> 729881.14 | G24: =SUM(G19:G23) -> 496708.99 | H24: =SUM(H19:H23) -> 819938.4 | I24: =SUM(D24:H24) -> 2543237.5
C26: Service Requests | D26: ='Service Requests'!I34 -> 118287.47 | E26: ='Service Requests'!J34 -> 118287.47 | F26: ='Service Requests'!K34 -> 118287.47 | G26: ='Service Requests'!L34 -> 118287.47 | H26: ='Service Requests'!M34 -> 118287.47 | I26: =SUM(D26:H26) -> 591437.33 | J26: at estimated volume
C28: Demand Requests | D28: ='Demand Requests'!N109 -> 299497.9 | E28: =D28 -> 299497.9 | F28: =E28 -> 299497.9 | G28: =F28 -> 299497.9 | H28: =G28 -> 299497.9 | I28: =SUM(D28:H28) -> 1497489.5 | J28: at estimated volume
C30: Exit
C31: ='One-time Charges'!B67 -> Termination for Convenience Fee | D31: ='One-time Charges'!H67 -> 6634171.3 | E31: ='One-time Charges'!I67 -> 10362539 | F31: ='One-time Charges'!J67 -> 8904112.2 | G31: ='One-time Charges'!K67 -> 7049765.8 | H31: ='One-time Charges'!L67 -> 4020820.4 | I31: =SUM(D31:H31) -> 36971409 | J31: Excluded from total
C32: ='One-time Charges'!B78 -> Remaining value Sole-use Assets | D32: =SUM('One-time Charges'!H78:H78) -> 0 | E32: =SUM('One-time Charges'!I78:I79) -> 0 | F32: =SUM('One-time Charges'!J78:J79) -> 0 | G32: =SUM('One-time Charges'!K78:K79) -> 0 | H32: =SUM('One-time Charges'!L78:L79) -> 0 | I32: =SUM(D32:H32) -> 0 | J32: Last year of Term included in total
C33: ='One-time Charges'!B93 -> Exit Assistance | D33: ='One-time Charges'!H93 -> 629264.84 | E33: ='One-time Charges'!I93 -> 629264.84 | F33: ='One-time Charges'!J93 -> 629264.84 | G33: ='One-time Charges'!K93 -> 629264.84 | H33: ='One-time Charges'!L93 -> 629264.84 | I33: =SUM(D33:H33) -> 3146324.2 | J33: Last year of Term included in total
C34: Options | D34: ='One-time Charges'!H104 -> 0 | E34: ='One-time Charges'!I22 -> 0 | F34: ='One-time Charges'!J22 -> 0 | G34: ='One-time Charges'!K22 -> 0 | H34: ='One-time Charges'!L22 -> 0 | I34: =SUM(D34:H34) -> 0 | J34: Last year of Term included in total
C35: Subtotal | D35: =SUM(D31:D34) -> 7263436.1 | E35: =SUM(E31:E34) -> 10991804 | F35: =SUM(F31:F34) -> 9533377.1 | G35: =SUM(G31:G34) -> 7679030.6 | H35: =SUM(H31:H34) -> 4650085.3 | I35: =SUM(D35:H35) -> 40117733
B38: Total Agreement Value | D38: Year 01 | E38: Year 02 | F38: Year 03 | G38: Year 04 | H38: Year 05 | I38: Total
C39: Total | D39: =D15+D24+D26+D28 -> 5852717.8 | E39: =E15+E24+E26+E28 -> 9905928.5 | F39: =F15+F24+F26+F28 -> 10168618 | G39: =G15+G24+G26+G28 -> 10255696 | H39: =H15+H24+H26+H28+H32+H33+H34 -> 10991373 | I39: =SUM(D39:H39) -> 47174332 | J39: At forecasted Baseline Quantities
C40: Without Options | D40: =D39-D14-D23 -> 5727116.5 | E40: =E39-E14-E23 -> 9699224.6 | F40: =F39-F14-F23 -> 9691116.5 | G40: =G39-G14-G23 -> 10022249 | H40: =H39-H14-H23-H35 -> 6118177.9 | I40: =SUM(I7:I13,I19:I22,I26,I28,I32:I33)-'One-time Charges'!M79 -> 48425029
J41: Total = Recurring Charges + these One-time Charges: • Transition and Transformation • Service Requests • Demand Requests • Remaining value Sole-use Assets • Exit Assistance

Sheet Monthly Recurring Charges
A1: Schedule 5.A (Pricing Sheet) – Monthly Recurring Charges (MRC)
BD2: =BD3/BD5 -> 2.0354609
AO3: Interim Services Unit Price Adjustment | BD3: =SUBTOTAL(9,BD6:BD63) -> 59305281
B4: Operational Services Domain | H4: € | I4: Monthly Unit Price | N4: # | O4: Baseline Quantity forecast | AP4: Service Start Date (month # after Agreement Start Date) | AQ4: Σ# | AW4: Σ€ | AX4: Forecasted Charges | BE4: i
C5: Service Component | P5: Year 01 month | AC5: Year 02 month | AR5: Y1+Y2 are averages, may show ramp-up | AX5: =AX8+AX11+AX18+AX29+AX39+AX58 -> 4099831.4 | AY5: =AY8+AY11+AY18+AY29+AY39+AY58 -> 6775978.7 | AZ5: =AZ8+AZ11+AZ18+AZ29+AZ39+AZ58 -> 6385236.6 | BA5: =BA8+BA11+BA18+BA29+BA39+BA58 -> 6081847.1 | BB5: =BB8+BB11+BB18+BB29+BB39+BB58 -> 5793151 | BD5: =BD8+BD11+BD18+BD29+BD39+BD58 -> 29136045
D6: Resource Unit | E6: Invoicing | F6: Baseline band | G6: Option | I6: Year 01 | J6: Year 02 | K6: Year 03 | L6: Year 04 | M6: Year 05 | O6: Current | P6: 1 | Q6: 2 | R6: 3 | S6: 4 | T6: 5 | U6: 6 | V6: 7 | W6: 8 | X6: 9 | Y6: 10 | Z6: 11 | AA6: 12 | AC6: 1 | AD6: 2 | AE6: 3 | AF6: 4 | AG6: 5 | AH6: 6 | AI6: 7 | AJ6: 8 | AK6: 9 | AL6: 10 | AM6: 11 | AN6: 12 | AR6: Year 01 | AS6: Year 02 | AT6: Year 03 | AU6: Year 04 | AV6: Year 05 | AX6: Year 01 | AY6: Year 02 | AZ6: Year 03 | BA6: Year 04 | BB6: Year 05 | BD6: Total | BF6: Remarks | BG6: Data source (indicative only, to be validated during Transition)'
P7: 1 | Q7: =P7+1 -> 2 | R7: =Q7+1 -> 3 | S7: =R7+1 -> 4 | T7: =S7+1 -> 5 | U7: =T7+1 -> 6 | V7: =U7+1 -> 7 | W7: =V7+1 -> 8 | X7: =W7+1 -> 9 | ... AA7: =Z7+1 -> 12 | AC7: =AA7+1 -> 13 | AD7: =AC7+1 -> 14 | AE7: =AD7+1 -> 15 | AF7: =AE7+1 -> 16 | AG7: =AF7+1 -> 17 | AH7: =AG7+1 -> 18 | AI7: =AH7+1 -> 19 | AJ7: =AI7+1 -> 20 | AK7: =AJ7+1 -> 21 | ... AN7: =AM7+1 -> 24 | AT7: 12 | AU7: 12 | AV7: 12 | AX7: =SUMIFS(AX8:AX63,$G8:$G63,"Option") -> 125601.37 | AY7: =SUMIFS(AY8:AY63,$G8:$G63,"Option") -> 206703.97 | AZ7: =SUMIFS(AZ8:AZ63,$G8:$G63,"Option") -> 244328.92 | BA7: =SUMIFS(BA8:BA63,$G8:$G63,"Option") -> 233447.17 | BB7: =SUMIFS(BB8:BB63,$G8:$G63,"Option") -> 223109.52 | BF7: Total of Options
B8: Service Integration and Management (SIAM) | P8: =IF(P$7<$AP$8,percPreTargetAdjustment,0%) -> 0 | Q8: =IF(Q$7<$AP$8,percPreTargetAdjustment,0%) -> 0 | R8: =IF(R$7<$AP$8,percPreTargetAdjustment,0%) -> 0 | S8: =IF(S$7<$AP$8,percPreTargetAdjustment,0%) -> 0 | T8: =IF(T$7<$AP$8,percPreTargetAdjustment,0%) -> 0 | U8: =IF(U$7<$AP$8,percPreTargetAdjustment,0%) -> 0 | V8: =IF(V$7<$AP$8,percPreTargetAdjustment,0%) -> 0 | W8: =IF(W$7<$AP$8,percPreTargetAdjustment,0%) -> 0 | ... AA8: =IF(AA$7<$AP$8,percPreTargetAdjustment,0%) -> 0 | AC8: =IF(AC$7<$AP$8,percPreTargetAdjustment,0%) -> 0 | AD8: =IF(AD$7<$AP$8,percPreTargetAdjustment,0%) -> 0 | AE8: =IF(AE$7<$AP$8,percPreTargetAdjustment,0%) -> 0 | AF8: =IF(AF$7<$AP$8,percPreTargetAdjustment,0%) -> 0 | AG8: =IF(AG$7<$AP$8,percPreTargetAdjustment,0%) -> 0 | AH8: =IF(AH$7<$AP$8,percPreTargetAdjustment,0%) -> 0 | AI8: =IF(AI$7<$AP$8,percPreTargetAdjustment,0%) -> 0 | AJ8: =IF(AJ$7<$AP$8,percPreTargetAdjustment,0%) -> 0 | ... AN8: =IF(AN$7<$AP$8,percPreTargetAdjustment,0%) -> 0 | AP8: 8 | AX8: =SUMIFS(AX9:AX10,$G9:$G10,"<>Option") -> 482083.4 | AY8: =SUMIFS(AY9:AY10,$G9:$G10,"<>Option") -> 818164.4 | AZ8: =SUMIFS(AZ9:AZ10,$G9:$G10,"<>Option") -> 793619.47 | BA8: =SUMIFS(BA9:BA10,$G9:$G10,"<>Option") -> 769810.88 | BB8: =SUMIFS(BB9:BB10,$G9:$G10,"<>Option") -> 746716.56 | BD8: =SUM(AX8:BB8) -> 3610394.7 | BF8: Domain totals exclude Options
C9: Service Integration and Management | D9: Fixed monthly | E9: central | F9: n/a | I9: 68869.057 | J9: 68180.367 | K9: 66134.956 | L9: 64150.907 | M9: 62226.38 | O9: 1 | U9: =$O$9 -> 1 | V9: =$O$9 -> 1 | W9: =$O$9 -> 1 | X9: =$O$9 -> 1 | Y9: =$O$9 -> 1 | Z9: =$O$9 -> 1 | AA9: =$O$9 -> 1 | AC9: =$O$9 -> 1 | AD9: =$O$9 -> 1 | AE9: =$O$9 -> 1 | AF9: =$O$9 -> 1 | AG9: =$O$9 -> 1 | AH9: =$O$9 -> 1 | AI9: =$O$9 -> 1 | AJ9: =$O$9 -> 1 | ... AN9: =$O$9 -> 1 | AR9: =IFERROR(AVERAGE(P9:AA9),0) -> 1 | AS9: =IFERROR(AVERAGE(AC9:AN9),0) -> 1 | AT9: =O9 -> 1 | AU9: =AT9 -> 1 | AV9: =AU9 -> 1 | AX9: =P9*(I9*(100%+P$8))+Q9*(I9*(100%+Q$8))+R9*(I9*(100%+R$8))+S9*(I9*(100%+S$8))+T9*(I9*(100%+T$8))+U9*(I9*(100%+U$8))+V9*(I9*(100%+V$8))+W9*(I9*(100%+W$8))+X9*(I9*(100%+X$8))+Y9*(I9*(100%+Y$8))+Z9*(I9*(100%+Z$8))+AA9*(I9*(100%+AA$8)) -> 482083.4 | AY9: =AC9*(J9*(100%+AC$8))+AD9*(J9*(100%+AD$8))+AE9*(J9*(100%+AE$8))+AF9*(J9*(100%+AF$8))+AG9*(J9*(100%+AG$8))+AH9*(J9*(100%+AH$8))+AI9*(J9*(100%+AI$8))+AJ9*(J9*(100%+AJ$8))+AK9*(J9*(100%+AK$8))+AL9*(J9*(100%+AL$8))+AM9*(J9*(100%+AM$8))+AN9*(J9*(100%+AN$8)) -> 818164.4 | AZ9: =K9*AT9*AT$7 -> 793619.47 | BA9: =L9*AU9*AU$7 -> 769810.88 | BB9: =M9*AV9*AV$7 -> 746716.56 | BD9: =SUM(AX9:BB9) -> 3610394.7 | BF9: Baseline band: +/- 2 Service Providers in Attachment 3.B3.L (Integrated Service Providers)
B11: Service Desk Services (SDS) | P11: =IF(P$7<$AP$11,percPreTargetAdjustment,0%) -> 0 | Q11: =IF(Q$7<$AP$11,percPreTargetAdjustment,0%) -> 0 | R11: =IF(R$7<$AP$11,percPreTargetAdjustment,0%) -> 0 | S11: =IF(S$7<$AP$11,percPreTargetAdjustment,0%) -> 0 | T11: =IF(T$7<$AP$11,percPreTargetAdjustment,0%) -> 0 | U11: =IF(U$7<$AP$11,percPreTargetAdjustment,0%) -> 0 | V11: =IF(V$7<$AP$11,percPreTargetAdjustment,0%) -> 0 | W11: =IF(W$7<$AP$11,percPreTargetAdjustment,0%) -> 0 | ... AA11: =IF(AA$7<$AP$11,percPreTargetAdjustment,0%) -> 0 | AC11: =IF(AC$7<$AP$11,percPreTargetAdjustment,0%) -> 0 | AD11: =IF(AD$7<$AP$11,percPreTargetAdjustment,0%) -> 0 | AE11: =IF(AE$7<$AP$11,percPreTargetAdjustment,0%) -> 0 | AF11: =IF(AF$7<$AP$11,percPreTargetAdjustment,0%) -> 0 | AG11: =IF(AG$7<$AP$11,percPreTargetAdjustment,0%) -> 0 | AH11: =IF(AH$7<$AP$11,percPreTargetAdjustment,0%) -> 0 | AI11: =IF(AI$7<$AP$11,percPreTargetAdjustment,0%) -> 0 | AJ11: =IF(AJ$7<$AP$11,percPreTargetAdjustment,0%) -> 0 | ... AN11: =IF(AN$7<$AP$11,percPreTargetAdjustment,0%) -> 0 | AX11: =SUMIFS(AX12:AX17,$G12:$G17,"<>Option") -> 375947.96 | AY11: =SUMIFS(AY12:AY17,$G12:$G17,"<>Option") -> 618702.92 | AZ11: =SUMIFS(AZ12:AZ17,$G12:$G17,"<>Option") -> 587767.78 | BA11: =SUMIFS(BA12:BA17,$G12:$G17,"<>Option") -> 558379.39 | BB11: =SUMIFS(BB12:BB17,$G12:$G17,"<>Option") -> 530460.42 | BD11: =SUM(AX11:BB11) -> 2671258.5
C12: Standard | D12: User | E12: central | F12: normal | I12: 3.3566782 | J12: 3.222411 | K12: 3.0612905 | L12: 2.908226 | M12: 2.7628147 | O12: 16000 | U12: =$O$12 -> 16000 | V12: =$O$12 -> 16000 | W12: =$O$12 -> 16000 | X12: =$O$12 -> 16000 | Y12: =$O$12 -> 16000 | Z12: =$O$12 -> 16000 | AA12: =$O$12 -> 16000 | AC12: =$O$12 -> 16000 | AD12: =$O$12 -> 16000 | AE12: =$O$12 -> 16000 | AF12: =$O$12 -> 16000 | AG12: =$O$12 -> 16000 | AH12: =$O$12 -> 16000 | AI12: =$O$12 -> 16000 | AJ12: =$O$12 -> 16000 | ... AN12: =$O$12 -> 16000 | AR12: =IFERROR(AVERAGE(P12:AA12),0) -> 16000 | AS12: =IFERROR(AVERAGE(AC12:AN12),0) -> 16000 | AT12: =O12 -> 16000 | AU12: =AT12 -> 16000 | AV12: =AU12 -> 16000 | AX12: =P12*(I12*(100%+P$11))+Q12*(I12*(100%+Q$11))+R12*(I12*(100%+R$11))+S12*(I12*(100%+S$11))+T12*(I12*(100%+T$11))+U12*(I12*(100%+U$11))+V12*(I12*(100%+V$11))+W12*(I12*(100%+W$11))+X12*(I12*(100%+X$11))+Y12*(I12*(100%+Y$11))+Z12*(I12*(100%+Z$11))+AA12*(I12*(100%+AA$11)) -> 375947.96 | AY12: =AC12*(J12*(100%+AC$11))+AD12*(J12*(100%+AD$11))+AE12*(J12*(100%+AE$11))+AF12*(J12*(100%+AF$11))+AG12*(J12*(100%+AG$11))+AH12*(J12*(100%+AH$11))+AI12*(J12*(100%+AI$11))+AJ12*(J12*(100%+AJ$11))+AK12*(J12*(100%+AK$11))+AL12*(J12*(100%+AL$11))+AM12*(J12*(100%+AM$11))+AN12*(J12*(100%+AN$11)) -> 618702.92 | AZ12: =K12*AT12*AT$7 -> 587767.78 | BA12: =L12*AU12*AU$7 -> 558379.39 | BB12: =M12*AV12*AV$7 -> 530460.42 | BD12: =SUM(AX12:BB12) -> 2671258.5 | BF12: Users in a country that may have a local-language add-on are counted too | BG12: Users File: Account Type "User" + "Generic"
C13: Brazilian Portuguese | D13: Fixed monthly | E13: local | F13: normal | G13: Option | I13: 4366.9152 | J13: 4192.2386 | K13: 3982.6267 | L13: 3783.4953 | M13: 3594.3206 | O13: 1 | U13: =$O$13 -> 1 | V13: =$O$13 -> 1 | W13: =$O$13 -> 1 | X13: =$O$13 -> 1 | Y13: =$O$13 -> 1 | Z13: =$O$13 -> 1 | AA13: =$O$13 -> 1 | AC13: =$O$13 -> 1 | AD13: =$O$13 -> 1 | AE13: =$O$13 -> 1 | AF13: =$O$13 -> 1 | AG13: =$O$13 -> 1 | AH13: =$O$13 -> 1 | AI13: =$O$13 -> 1 | AJ13: =$O$13 -> 1 | ... AN13: =$O$13 -> 1 | AR13: =IFERROR(AVERAGE(P13:AA13),0) -> 1 | AS13: =IFERROR(AVERAGE(AC13:AN13),0) -> 1 | AT13: =O13 -> 1 | AU13: =AT13 -> 1 | AV13: =AU13 -> 1 | AX13: =P13*(I13*(100%+P$11))+Q13*(I13*(100%+Q$11))+R13*(I13*(100%+R$11))+S13*(I13*(100%+S$11))+T13*(I13*(100%+T$11))+U13*(I13*(100%+U$11))+V13*(I13*(100%+V$11))+W13*(I13*(100%+W$11))+X13*(I13*(100%+X$11))+Y13*(I13*(100%+Y$11))+Z13*(I13*(100%+Z$11))+AA13*(I13*(100%+AA$11)) -> 30568.406 | AY13: =AC13*(J13*(100%+AC$11))+AD13*(J13*(100%+AD$11))+AE13*(J13*(100%+AE$11))+AF13*(J13*(100%+AF$11))+AG13*(J13*(100%+AG$11))+AH13*(J13*(100%+AH$11))+AI13*(J13*(100%+AI$11))+AJ13*(J13*(100%+AJ$11))+AK13*(J13*(100%+AK$11))+AL13*(J13*(100%+AL$11))+AM13*(J13*(100%+AM$11))+AN13*(J13*(100%+AN$11)) -> 50306.863 | AZ13: =K13*AT13*AT$7 -> 47791.52 | BA13: =L13*AU13*AU$7 -> 45401.944 | BB13: =M13*AV13*AV$7 -> 43131.847 | BD13: =SUM(AX13:BB13) -> 217200.58 | BF13: Baseline band measured on number of Users in Brazil: 2050 | BG13: Users File: Country "Brazil", Account Type "User"
C14: German | D14: Fixed monthly | E14: local | F14: normal | G14: Option | I14: 5651.4585 | J14: 5425.4002 | K14: 5154.1302 | L14: 4896.4237 | M14: 4651.6025 | O14: 1 | U14: =$O$14 -> 1 | V14: =$O$14 -> 1 | W14: =$O$14 -> 1 | X14: =$O$14 -> 1 | Y14: =$O$14 -> 1 | Z14: =$O$14 -> 1 | AA14: =$O$14 -> 1 | AC14: =$O$14 -> 1 | AD14: =$O$14 -> 1 | AE14: =$O$14 -> 1 | AF14: =$O$14 -> 1 | AG14: =$O$14 -> 1 | AH14: =$O$14 -> 1 | AI14: =$O$14 -> 1 | AJ14: =$O$14 -> 1 | ... AN14: =$O$14 -> 1 | AR14: =IFERROR(AVERAGE(P14:AA14),0) -> 1 | AS14: =IFERROR(AVERAGE(AC14:AN14),0) -> 1 | AT14: =O14 -> 1 | AU14: =AT14 -> 1 | AV14: =AU14 -> 1 | AX14: =P14*(I14*(100%+P$11))+Q14*(I14*(100%+Q$11))+R14*(I14*(100%+R$11))+S14*(I14*(100%+S$11))+T14*(I14*(100%+T$11))+U14*(I14*(100%+U$11))+V14*(I14*(100%+V$11))+W14*(I14*(100%+W$11))+X14*(I14*(100%+X$11))+Y14*(I14*(100%+Y$11))+Z14*(I14*(100%+Z$11))+AA14*(I14*(100%+AA$11)) -> 39560.21 | AY14: =AC14*(J14*(100%+AC$11))+AD14*(J14*(100%+AD$11))+AE14*(J14*(100%+AE$11))+AF14*(J14*(100%+AF$11))+AG14*(J14*(100%+AG$11))+AH14*(J14*(100%+AH$11))+AI14*(J14*(100%+AI$11))+AJ14*(J14*(100%+AJ$11))+AK14*(J14*(100%+AK$11))+AL14*(J14*(100%+AL$11))+AM14*(J14*(100%+AM$11))+AN14*(J14*(100%+AN$11)) -> 65104.802 | AZ14: =K14*AT14*AT$7 -> 61849.562 | BA14: =L14*AU14*AU$7 -> 58757.084 | BB14: =M14*AV14*AV$7 -> 55819.23 | BD14: =SUM(AX14:BB14) -> 281090.89 | BF14: Baseline band measured on number of Users in Germany: 1515 | BG14: Users File: Country "Germany", Account Type "User"
C15: French | D15: Fixed monthly | E15: local | F15: normal | G15: Option | I15: 5039.3869 | J15: 4837.8114 | K15: 4595.9208 | L15: 4366.1248 | M15: 4147.8185 | O15: 1 | U15: =$O$15 -> 1 | V15: =$O$15 -> 1 | W15: =$O$15 -> 1 | X15: =$O$15 -> 1 | Y15: =$O$15 -> 1 | Z15: =$O$15 -> 1 | AA15: =$O$15 -> 1 | AC15: =$O$15 -> 1 | AD15: =$O$15 -> 1 | AE15: =$O$15 -> 1 | AF15: =$O$15 -> 1 | AG15: =$O$15 -> 1 | AH15: =$O$15 -> 1 | AI15: =$O$15 -> 1 | AJ15: =$O$15 -> 1 | ... AN15: =$O$15 -> 1 | AR15: =IFERROR(AVERAGE(P15:AA15),0) -> 1 | AS15: =IFERROR(AVERAGE(AC15:AN15),0) -> 1 | AT15: =O15 -> 1 | AU15: =AT15 -> 1 | AV15: =AU15 -> 1 | AX15: =P15*(I15*(100%+P$11))+Q15*(I15*(100%+Q$11))+R15*(I15*(100%+R$11))+S15*(I15*(100%+S$11))+T15*(I15*(100%+T$11))+U15*(I15*(100%+U$11))+V15*(I15*(100%+V$11))+W15*(I15*(100%+W$11))+X15*(I15*(100%+X$11))+Y15*(I15*(100%+Y$11))+Z15*(I15*(100%+Z$11))+AA15*(I15*(100%+AA$11)) -> 35275.708 | AY15: =AC15*(J15*(100%+AC$11))+AD15*(J15*(100%+AD$11))+AE15*(J15*(100%+AE$11))+AF15*(J15*(100%+AF$11))+AG15*(J15*(100%+AG$11))+AH15*(J15*(100%+AH$11))+AI15*(J15*(100%+AI$11))+AJ15*(J15*(100%+AJ$11))+AK15*(J15*(100%+AK$11))+AL15*(J15*(100%+AL$11))+AM15*(J15*(100%+AM$11))+AN15*(J15*(100%+AN$11)) -> 58053.737 | AZ15: =K15*AT15*AT$7 -> 55151.05 | BA15: =L15*AU15*AU$7 -> 52393.497 | BB15: =M15*AV15*AV$7 -> 49773.822 | BD15: =SUM(AX15:BB15) -> 250647.81 | BF15: Baseline band measured on number of Users in France: 872 | BG15: Users File: Country "France", Account Type "User"
C16: Mandarin | D16: Fixed monthly | E16: local | F16: normal | G16: Option | I16: 2885.2922 | J16: 2769.8805 | K16: 2631.3865 | L16: 2499.8172 | M16: 2374.8263 | O16: 1 | U16: =$O$16 -> 1 | V16: =$O$16 -> 1 | W16: =$O$16 -> 1 | X16: =$O$16 -> 1 | Y16: =$O$16 -> 1 | Z16: =$O$16 -> 1 | AA16: =$O$16 -> 1 | AC16: =$O$16 -> 1 | AD16: =$O$16 -> 1 | AE16: =$O$16 -> 1 | AF16: =$O$16 -> 1 | AG16: =$O$16 -> 1 | AH16: =$O$16 -> 1 | AI16: =$O$16 -> 1 | AJ16: =$O$16 -> 1 | ... AN16: =$O$16 -> 1 | AR16: =IFERROR(AVERAGE(P16:AA16),0) -> 1 | AS16: =IFERROR(AVERAGE(AC16:AN16),0) -> 1 | AT16: =O16 -> 1 | AU16: =AT16 -> 1 | AV16: =AU16 -> 1 | AX16: =P16*(I16*(100%+P$11))+Q16*(I16*(100%+Q$11))+R16*(I16*(100%+R$11))+S16*(I16*(100%+S$11))+T16*(I16*(100%+T$11))+U16*(I16*(100%+U$11))+V16*(I16*(100%+V$11))+W16*(I16*(100%+W$11))+X16*(I16*(100%+X$11))+Y16*(I16*(100%+Y$11))+Z16*(I16*(100%+Z$11))+AA16*(I16*(100%+AA$11)) -> 20197.046 | AY16: =AC16*(J16*(100%+AC$11))+AD16*(J16*(100%+AD$11))+AE16*(J16*(100%+AE$11))+AF16*(J16*(100%+AF$11))+AG16*(J16*(100%+AG$11))+AH16*(J16*(100%+AH$11))+AI16*(J16*(100%+AI$11))+AJ16*(J16*(100%+AJ$11))+AK16*(J16*(100%+AK$11))+AL16*(J16*(100%+AL$11))+AM16*(J16*(100%+AM$11))+AN16*(J16*(100%+AN$11)) -> 33238.566 | AZ16: =K16*AT16*AT$7 -> 31576.638 | BA16: =L16*AU16*AU$7 -> 29997.806 | BB16: =M16*AV16*AV$7 -> 28497.916 | BD16: =SUM(AX16:BB16) -> 143507.97 | BF16: Baseline band measured on number of Users in China: 213 | BG16: Users File: Country "China", Account Type "User"
B18: Workplace Services (WPS) | P18: =IF(P$7<$AP$18,percPreTargetAdjustment,0%) -> 0 | Q18: =IF(Q$7<$AP$18,percPreTargetAdjustment,0%) -> 0 | R18: =IF(R$7<$AP$18,percPreTargetAdjustment,0%) -> 0 | S18: =IF(S$7<$AP$18,percPreTargetAdjustment,0%) -> 0 | T18: =IF(T$7<$AP$18,percPreTargetAdjustment,0%) -> 0 | U18: =IF(U$7<$AP$18,percPreTargetAdjustment,0%) -> 0 | V18: =IF(V$7<$AP$18,percPreTargetAdjustment,0%) -> 0 | W18: =IF(W$7<$AP$18,percPreTargetAdjustment,0%) -> 0 | ... AA18: =IF(AA$7<$AP$18,percPreTargetAdjustment,0%) -> 0 | AC18: =IF(AC$7<$AP$18,percPreTargetAdjustment,0%) -> 0 | AD18: =IF(AD$7<$AP$18,percPreTargetAdjustment,0%) -> 0 | AE18: =IF(AE$7<$AP$18,percPreTargetAdjustment,0%) -> 0 | AF18: =IF(AF$7<$AP$18,percPreTargetAdjustment,0%) -> 0 | AG18: =IF(AG$7<$AP$18,percPreTargetAdjustment,0%) -> 0 | AH18: =IF(AH$7<$AP$18,percPreTargetAdjustment,0%) -> 0 | AI18: =IF(AI$7<$AP$18,percPreTargetAdjustment,0%) -> 0 | AJ18: =IF(AJ$7<$AP$18,percPreTargetAdjustment,0%) -> 0 | ... AN18: =IF(AN$7<$AP$18,percPreTargetAdjustment,0%) -> 0 | AX18: =SUMIFS(AX19:AX28,$G19:$G28,"<>Option") -> 1959711.2 | AY18: =SUMIFS(AY19:AY28,$G19:$G28,"<>Option") -> 3225124.7 | AZ18: =SUMIFS(AZ19:AZ28,$G19:$G28,"<>Option") -> 3027947.7 | BA18: =SUMIFS(BA19:BA28,$G19:$G28,"<>Option") -> 2876550.3 | BB18: =SUMIFS(BB19:BB28,$G19:$G28,"<>Option") -> 2732722.8 | BD18: =SUM(AX18:BB18) -> 13822057
C19: Managed PC | D19: PC device | E19: local | F19: normal | I19: 19.431735 | J19: 18.654465 | K19: 17.721742 | L19: 16.835655 | M19: 15.993872 | O19: 10156 | U19: =$O$19 -> 10156 | V19: =$O$19 -> 10156 | W19: =$O$19 -> 10156 | X19: =$O$19 -> 10156 | Y19: =$O$19 -> 10156 | Z19: =$O$19 -> 10156 | AA19: =$O$19 -> 10156 | AC19: =$O$19 -> 10156 | AD19: =$O$19 -> 10156 | AE19: =$O$19 -> 10156 | AF19: =$O$19 -> 10156 | AG19: =$O$19 -> 10156 | AH19: =$O$19 -> 10156 | AI19: =$O$19 -> 10156 | AJ19: =$O$19 -> 10156 | ... AN19: =$O$19 -> 10156 | AR19: =IFERROR(AVERAGE(P19:AA19),0) -> 10156 | AS19: =IFERROR(AVERAGE(AC19:AN19),0) -> 10156 | AT19: =O19 -> 10156 | AU19: =AT19 -> 10156 | AV19: =AU19 -> 10156 | AX19: =P19*(I19*(100%+P$18))+Q19*(I19*(100%+Q$18))+R19*(I19*(100%+R$18))+S19*(I19*(100%+S$18))+T19*(I19*(100%+T$18))+U19*(I19*(100%+U$18))+V19*(I19*(100%+V$18))+W19*(I19*(100%+W$18))+X19*(I19*(100%+X$18))+Y19*(I19*(100%+Y$18))+Z19*(I19*(100%+Z$18))+AA19*(I19*(100%+AA$18)) -> 1381440.9 | AY19: =AC19*(J19*(100%+AC$18))+AD19*(J19*(100%+AD$18))+AE19*(J19*(100%+AE$18))+AF19*(J19*(100%+AF$18))+AG19*(J19*(100%+AG$18))+AH19*(J19*(100%+AH$18))+AI19*(J19*(100%+AI$18))+AJ19*(J19*(100%+AJ$18))+AK19*(J19*(100%+AK$18))+AL19*(J19*(100%+AL$18))+AM19*(J19*(100%+AM$18))+AN19*(J19*(100%+AN$18)) -> 2273457 | AZ19: =K19*AT19*AT$7 -> 2159784.2 | BA19: =L19*AU19*AU$7 -> 2051795 | BB19: =M19*AV19*AV$7 -> 1949205.2 | BD19: =SUM(AX19:BB19) -> 9815682.2 | BF19: For OpEx ( DaaS) + CapEx (Non-DaaS) PCs | BG19: Device CMDB File: Total device count
C20: Uplift on 'Managed PC' for ReadyTech kiosk | D20: PC device | E20: local | F20: wide | G20: Option | I20: =I19+Devices!$V$9 -> 41.676782 | J20: =J19+Devices!$V$9 -> 40.899512 | K20: =K19+Devices!$V$9 -> 39.966789 | L20: =L19+Devices!$V$9 -> 39.080702 | M20: =M19+Devices!$V$9 -> 38.238919 | O20: 0 | U20: =$O$20 -> 0 | V20: =$O$20 -> 0 | W20: =$O$20 -> 0 | X20: =$O$20 -> 0 | Y20: =$O$20 -> 0 | Z20: =$O$20 -> 0 | AA20: =$O$20 -> 0 | AC20: =$O$20 -> 0 | AD20: =$O$20 -> 0 | AE20: =$O$20 -> 0 | AF20: =$O$20 -> 0 | AG20: =$O$20 -> 0 | AH20: =$O$20 -> 0 | AI20: =$O$20 -> 0 | AJ20: =$O$20 -> 0 | ... AN20: =$O$20 -> 0 | AR20: =IFERROR(AVERAGE(P20:AA20),0) -> 0 | AS20: =IFERROR(AVERAGE(AC20:AN20),0) -> 0 | AT20: 100 | AU20: =AT20 -> 100 | AV20: =AU20 -> 100 | AX20: =P20*(I20*(100%+P$18))+Q20*(I20*(100%+Q$18))+R20*(I20*(100%+R$18))+S20*(I20*(100%+S$18))+T20*(I20*(100%+T$18))+U20*(I20*(100%+U$18))+V20*(I20*(100%+V$18))+W20*(I20*(100%+W$18))+X20*(I20*(100%+X$18))+Y20*(I20*(100%+Y$18))+Z20*(I20*(100%+Z$18))+AA20*(I20*(100%+AA$18)) -> 0 | AY20: =AC20*(J20*(100%+AC$18))+AD20*(J20*(100%+AD$18))+AE20*(J20*(100%+AE$18))+AF20*(J20*(100%+AF$18))+AG20*(J20*(100%+AG$18))+AH20*(J20*(100%+AH$18))+AI20*(J20*(100%+AI$18))+AJ20*(J20*(100%+AJ$18))+AK20*(J20*(100%+AK$18))+AL20*(J20*(100%+AL$18))+AM20*(J20*(100%+AM$18))+AN20*(J20*(100%+AN$18)) -> 0 | AZ20: =K20*AT20*AT$7 -> 47960.147 | BA20: =L20*AU20*AU$7 -> 46896.842 | BB20: =M20*AV20*AV$7 -> 45886.703 | BD20: =SUM(AX20:BB20) -> 140743.69
C21: Company Smartphone and Company Tablet | D21: Mobile Device | E21: local | F21: wide | I21: 13.474287 | J21: 12.935315 | K21: 12.28855 | L21: 11.674122 | M21: 11.090416 | O21: 459 | U21: =$O$21 -> 459 | V21: =$O$21 -> 459 | W21: =$O$21 -> 459 | X21: =$O$21 -> 459 | Y21: =$O$21 -> 459 | Z21: =$O$21 -> 459 | AA21: =$O$21 -> 459 | AC21: =$O$21 -> 459 | AD21: =$O$21 -> 459 | AE21: =$O$21 -> 459 | AF21: =$O$21 -> 459 | AG21: =$O$21 -> 459 | AH21: =$O$21 -> 459 | AI21: =$O$21 -> 459 | AJ21: =$O$21 -> 459 | ... AN21: =$O$21 -> 459 | AR21: =IFERROR(AVERAGE(P21:AA21),0) -> 459 | AS21: =IFERROR(AVERAGE(AC21:AN21),0) -> 459 | AT21: =O21 -> 459 | AU21: =AT21 -> 459 | AV21: =AU21 -> 459 | AX21: =P21*(I21*(100%+P$18))+Q21*(I21*(100%+Q$18))+R21*(I21*(100%+R$18))+S21*(I21*(100%+S$18))+T21*(I21*(100%+T$18))+U21*(I21*(100%+U$18))+V21*(I21*(100%+V$18))+W21*(I21*(100%+W$18))+X21*(I21*(100%+X$18))+Y21*(I21*(100%+Y$18))+Z21*(I21*(100%+Z$18))+AA21*(I21*(100%+AA$18)) -> 43292.884 | AY21: =AC21*(J21*(100%+AC$18))+AD21*(J21*(100%+AD$18))+AE21*(J21*(100%+AE$18))+AF21*(J21*(100%+AF$18))+AG21*(J21*(100%+AG$18))+AH21*(J21*(100%+AH$18))+AI21*(J21*(100%+AI$18))+AJ21*(J21*(100%+AJ$18))+AK21*(J21*(100%+AK$18))+AL21*(J21*(100%+AL$18))+AM21*(J21*(100%+AM$18))+AN21*(J21*(100%+AN$18)) -> 71247.717 | AZ21: =K21*AT21*AT$7 -> 67685.331 | BA21: =L21*AU21*AU$7 -> 64301.065 | BB21: =M21*AV21*AV$7 -> 61086.011 | BD21: =SUM(AX21:BB21) -> 307613.01 | BF21: Baseline band is for Company Smartphone + Company Tablet + Managed Mobile | BG21: October Factory Tables Invoice from Accenture
C22: Managed Mobile | D22: Mobile Device | E22: local | F22: wide | I22: 1.7597105 | J22: 1.6893221 | K22: 1.604856 | L22: 1.5246132 | M22: 1.4483826 | O22: 9688 | U22: =$O$22 -> 9688 | V22: =$O$22 -> 9688 | W22: =$O$22 -> 9688 | X22: =$O$22 -> 9688 | Y22: =$O$22 -> 9688 | Z22: =$O$22 -> 9688 | AA22: =$O$22 -> 9688 | AC22: =$O$22 -> 9688 | AD22: =$O$22 -> 9688 | AE22: =$O$22 -> 9688 | AF22: =$O$22 -> 9688 | AG22: =$O$22 -> 9688 | AH22: =$O$22 -> 9688 | AI22: =$O$22 -> 9688 | AJ22: =$O$22 -> 9688 | ... AN22: =$O$22 -> 9688 | AR22: =IFERROR(AVERAGE(P22:AA22),0) -> 9688 | AS22: =IFERROR(AVERAGE(AC22:AN22),0) -> 9688 | AT22: =O22 -> 9688 | AU22: =AT22 -> 9688 | AV22: =AU22 -> 9688 | AX22: =P22*(I22*(100%+P$18))+Q22*(I22*(100%+Q$18))+R22*(I22*(100%+R$18))+S22*(I22*(100%+S$18))+T22*(I22*(100%+T$18))+U22*(I22*(100%+U$18))+V22*(I22*(100%+V$18))+W22*(I22*(100%+W$18))+X22*(I22*(100%+X$18))+Y22*(I22*(100%+Y$18))+Z22*(I22*(100%+Z$18))+AA22*(I22*(100%+AA$18)) -> 119336.53 | AY22: =AC22*(J22*(100%+AC$18))+AD22*(J22*(100%+AD$18))+AE22*(J22*(100%+AE$18))+AF22*(J22*(100%+AF$18))+AG22*(J22*(100%+AG$18))+AH22*(J22*(100%+AH$18))+AI22*(J22*(100%+AI$18))+AJ22*(J22*(100%+AJ$18))+AK22*(J22*(100%+AK$18))+AL22*(J22*(100%+AL$18))+AM22*(J22*(100%+AM$18))+AN22*(J22*(100%+AN$18)) -> 196393.83 | AZ22: =K22*AT22*AT$7 -> 186574.14 | BA22: =L22*AU22*AU$7 -> 177245.43 | BB22: =M22*AV22*AV$7 -> 168383.16 | BD22: =SUM(AX22:BB22) -> 847933.1 | BF22: Baseline band is for Company Smartphone + Company Tablet + Managed Mobile | BG22: InTune File: minus factory tablet volume from Accenture invoicing.
C23: Microsoft 365 full usage | D23: User | E23: local | F23: normal | I23: 3.0329179 | J23: 2.9116012 | K23: 2.7660212 | L23: 2.6277201 | M23: 2.4963341 | O23: 12250 | U23: =$O$23 -> 12250 | V23: =$O$23 -> 12250 | W23: =$O$23 -> 12250 | X23: =$O$23 -> 12250 | Y23: =$O$23 -> 12250 | Z23: =$O$23 -> 12250 | AA23: =$O$23 -> 12250 | AC23: =$O$23 -> 12250 | AD23: =$O$23 -> 12250 | AE23: =$O$23 -> 12250 | AF23: =$O$23 -> 12250 | AG23: =$O$23 -> 12250 | AH23: =$O$23 -> 12250 | AI23: =$O$23 -> 12250 | AJ23: =$O$23 -> 12250 | ... AN23: =$O$23 -> 12250 | AR23: =IFERROR(AVERAGE(P23:AA23),0) -> 12250 | AS23: =IFERROR(AVERAGE(AC23:AN23),0) -> 12250 | AT23: =O23 -> 12250 | AU23: =AT23 -> 12250 | AV23: =AU23 -> 12250 | AX23: =P23*(I23*(100%+P$18))+Q23*(I23*(100%+Q$18))+R23*(I23*(100%+R$18))+S23*(I23*(100%+S$18))+T23*(I23*(100%+T$18))+U23*(I23*(100%+U$18))+V23*(I23*(100%+V$18))+W23*(I23*(100%+W$18))+X23*(I23*(100%+X$18))+Y23*(I23*(100%+Y$18))+Z23*(I23*(100%+Z$18))+AA23*(I23*(100%+AA$18)) -> 260072.71 | AY23: =AC23*(J23*(100%+AC$18))+AD23*(J23*(100%+AD$18))+AE23*(J23*(100%+AE$18))+AF23*(J23*(100%+AF$18))+AG23*(J23*(100%+AG$18))+AH23*(J23*(100%+AH$18))+AI23*(J23*(100%+AI$18))+AJ23*(J23*(100%+AJ$18))+AK23*(J23*(100%+AK$18))+AL23*(J23*(100%+AL$18))+AM23*(J23*(100%+AM$18))+AN23*(J23*(100%+AN$18)) -> 428005.38 | AZ23: =K23*AT23*AT$7 -> 406605.11 | BA23: =L23*AU23*AU$7 -> 386274.85 | BB23: =M23*AV23*AV$7 -> 366961.11 | BD23: =SUM(AX23:BB23) -> 1847919.2 | BG23: Users File: O365 License Type "Enterprise"
C24: Microsoft 365 light usage | D24: User | E24: local | F24: wide | I24: 2.4515913 | J24: 2.3535276 | K24: 2.2358512 | L24: 2.1240587 | M24: 2.0178557 | O24: 2600 | U24: =$O$24 -> 2600 | V24: =$O$24 -> 2600 | W24: =$O$24 -> 2600 | X24: =$O$24 -> 2600 | Y24: =$O$24 -> 2600 | Z24: =$O$24 -> 2600 | AA24: =$O$24 -> 2600 | AC24: =$O$24 -> 2600 | AD24: =$O$24 -> 2600 | AE24: =$O$24 -> 2600 | AF24: =$O$24 -> 2600 | AG24: =$O$24 -> 2600 | AH24: =$O$24 -> 2600 | AI24: =$O$24 -> 2600 | AJ24: =$O$24 -> 2600 | ... AN24: =$O$24 -> 2600 | AR24: =IFERROR(AVERAGE(P24:AA24),0) -> 2600 | AS24: =IFERROR(AVERAGE(AC24:AN24),0) -> 2600 | AT24: =O24 -> 2600 | AU24: =AT24 -> 2600 | AV24: =AU24 -> 2600 | AX24: =P24*(I24*(100%+P$18))+Q24*(I24*(100%+Q$18))+R24*(I24*(100%+R$18))+S24*(I24*(100%+S$18))+T24*(I24*(100%+T$18))+U24*(I24*(100%+U$18))+V24*(I24*(100%+V$18))+W24*(I24*(100%+W$18))+X24*(I24*(100%+X$18))+Y24*(I24*(100%+Y$18))+Z24*(I24*(100%+Z$18))+AA24*(I24*(100%+AA$18)) -> 44618.961 | AY24: =AC24*(J24*(100%+AC$18))+AD24*(J24*(100%+AD$18))+AE24*(J24*(100%+AE$18))+AF24*(J24*(100%+AF$18))+AG24*(J24*(100%+AG$18))+AH24*(J24*(100%+AH$18))+AI24*(J24*(100%+AI$18))+AJ24*(J24*(100%+AJ$18))+AK24*(J24*(100%+AK$18))+AL24*(J24*(100%+AL$18))+AM24*(J24*(100%+AM$18))+AN24*(J24*(100%+AN$18)) -> 73430.062 | AZ24: =K24*AT24*AT$7 -> 69758.559 | BA24: =L24*AU24*AU$7 -> 66270.631 | BB24: =M24*AV24*AV$7 -> 62957.099 | BD24: =SUM(AX24:BB24) -> 317035.31 | BG24: Users File: O365 License Type "Firstline"
C25: Teams meeting room platform management | D25: Fixed monthly | E25: central | F25: n/a | I25: 6836.261 | J25: 6562.8106 | K25: 6234.6701 | L25: 5922.9366 | M25: 5626.7897 | O25: 1 | U25: =$O$25 -> 1 | V25: =$O$25 -> 1 | W25: =$O$25 -> 1 | X25: =$O$25 -> 1 | Y25: =$O$25 -> 1 | Z25: =$O$25 -> 1 | AA25: =$O$25 -> 1 | AC25: =$O$25 -> 1 | AD25: =$O$25 -> 1 | AE25: =$O$25 -> 1 | AF25: =$O$25 -> 1 | AG25: =$O$25 -> 1 | AH25: =$O$25 -> 1 | AI25: =$O$25 -> 1 | AJ25: =$O$25 -> 1 | ... AN25: =$O$25 -> 1 | AR25: =IFERROR(AVERAGE(P25:AA25),0) -> 1 | AS25: =IFERROR(AVERAGE(AC25:AN25),0) -> 1 | AT25: =O25 -> 1 | AU25: =AT25 -> 1 | AV25: =AU25 -> 1 | AX25: =P25*(I25*(100%+P$18))+Q25*(I25*(100%+Q$18))+R25*(I25*(100%+R$18))+S25*(I25*(100%+S$18))+T25*(I25*(100%+T$18))+U25*(I25*(100%+U$18))+V25*(I25*(100%+V$18))+W25*(I25*(100%+W$18))+X25*(I25*(100%+X$18))+Y25*(I25*(100%+Y$18))+Z25*(I25*(100%+Z$18))+AA25*(I25*(100%+AA$18)) -> 47853.827 | AY25: =AC25*(J25*(100%+AC$18))+AD25*(J25*(100%+AD$18))+AE25*(J25*(100%+AE$18))+AF25*(J25*(100%+AF$18))+AG25*(J25*(100%+AG$18))+AH25*(J25*(100%+AH$18))+AI25*(J25*(100%+AI$18))+AJ25*(J25*(100%+AJ$18))+AK25*(J25*(100%+AK$18))+AL25*(J25*(100%+AL$18))+AM25*(J25*(100%+AM$18))+AN25*(J25*(100%+AN$18)) -> 78753.727 | AZ25: =K25*AT25*AT$7 -> 74816.041 | BA25: =L25*AU25*AU$7 -> 71075.239 | BB25: =M25*AV25*AV$7 -> 67521.477 | BD25: =SUM(AX25:BB25) -> 340020.31
C26: Azure Virtual Desktop | D26: Workspace/Host Pool | E26: central | F26: n/a | I26: 892.49796 | J26: 856.79804 | K26: 813.95814 | L26: 773.26023 | M26: 734.59722 | O26: 5 | U26: =$O$26 -> 5 | V26: =$O$26 -> 5 | W26: =$O$26 -> 5 | X26: =$O$26 -> 5 | Y26: =$O$26 -> 5 | Z26: =$O$26 -> 5 | AA26: =$O$26 -> 5 | AC26: =$O$26 -> 5 | AD26: =$O$26 -> 5 | AE26: =$O$26 -> 5 | AF26: =$O$26 -> 5 | AG26: =$O$26 -> 5 | AH26: =$O$26 -> 5 | AI26: =$O$26 -> 5 | AJ26: =$O$26 -> 5 | ... AN26: =$O$26 -> 5 | AR26: =IFERROR(AVERAGE(P26:AA26),0) -> 5 | AS26: =IFERROR(AVERAGE(AC26:AN26),0) -> 5 | AT26: =O26 -> 5 | AU26: =AT26 -> 5 | AV26: =AU26 -> 5 | AX26: =P26*(I26*(100%+P$18))+Q26*(I26*(100%+Q$18))+R26*(I26*(100%+R$18))+S26*(I26*(100%+S$18))+T26*(I26*(100%+T$18))+U26*(I26*(100%+U$18))+V26*(I26*(100%+V$18))+W26*(I26*(100%+W$18))+X26*(I26*(100%+X$18))+Y26*(I26*(100%+Y$18))+Z26*(I26*(100%+Z$18))+AA26*(I26*(100%+AA$18)) -> 31237.429 | AY26: =AC26*(J26*(100%+AC$18))+AD26*(J26*(100%+AD$18))+AE26*(J26*(100%+AE$18))+AF26*(J26*(100%+AF$18))+AG26*(J26*(100%+AG$18))+AH26*(J26*(100%+AH$18))+AI26*(J26*(100%+AI$18))+AJ26*(J26*(100%+AJ$18))+AK26*(J26*(100%+AK$18))+AL26*(J26*(100%+AL$18))+AM26*(J26*(100%+AM$18))+AN26*(J26*(100%+AN$18)) -> 51407.882 | AZ26: =K26*AT26*AT$7 -> 48837.488 | BA26: =L26*AU26*AU$7 -> 46395.614 | BB26: =M26*AV26*AV$7 -> 44075.833 | BD26: =SUM(AX26:BB26) -> 221954.25
C27: CIS Managed OS for On-site and Azure WPS servers | D27: =D34 -> OS instance | E27: =E34 -> local | F27: =$F$33 -> normal | I27: =I34 -> 16.918712 | J27: =J34 -> 16.241964 | K27: =K34 -> 15.429866 | L27: =L34 -> 14.658372 | M27: =M34 -> 13.925454 | O27: 269 | U27: =$O$27 -> 269 | V27: =$O$27 -> 269 | W27: =$O$27 -> 269 | X27: =$O$27 -> 269 | Y27: =$O$27 -> 269 | Z27: =$O$27 -> 269 | AA27: =$O$27 -> 269 | AC27: =$O$27 -> 269 | AD27: =$O$27 -> 269 | AE27: =$O$27 -> 269 | AF27: =$O$27 -> 269 | AG27: =$O$27 -> 269 | AH27: =$O$27 -> 269 | AI27: =$O$27 -> 269 | AJ27: =$O$27 -> 269 | ... AN27: =$O$27 -> 269 | AR27: =IFERROR(AVERAGE(P27:AA27),0) -> 269 | AS27: =IFERROR(AVERAGE(AC27:AN27),0) -> 269 | AT27: 75 | AU27: =AT27 -> 75 | AV27: =AU27 -> 75 | AX27: =P27*(I27*(100%+P$18))+Q27*(I27*(100%+Q$18))+R27*(I27*(100%+R$18))+S27*(I27*(100%+S$18))+T27*(I27*(100%+T$18))+U27*(I27*(100%+U$18))+V27*(I27*(100%+V$18))+W27*(I27*(100%+W$18))+X27*(I27*(100%+X$18))+Y27*(I27*(100%+Y$18))+Z27*(I27*(100%+Z$18))+AA27*(I27*(100%+AA$18)) -> 31857.935 | AY27: =AC27*(J27*(100%+AC$18))+AD27*(J27*(100%+AD$18))+AE27*(J27*(100%+AE$18))+AF27*(J27*(100%+AF$18))+AG27*(J27*(100%+AG$18))+AH27*(J27*(100%+AH$18))+AI27*(J27*(100%+AI$18))+AJ27*(J27*(100%+AJ$18))+AK27*(J27*(100%+AK$18))+AL27*(J27*(100%+AL$18))+AM27*(J27*(100%+AM$18))+AN27*(J27*(100%+AN$18)) -> 52429.059 | AZ27: =K27*AT27*AT$7 -> 13886.879 | BA27: =L27*AU27*AU$7 -> 13192.535 | BB27: =M27*AV27*AV$7 -> 12532.908 | BD27: =SUM(AX27:BB27) -> 123899.32 | BG27: Server CMDB file: Server Function "EUS", Hosting Location "On Prem"
B29: Cloud and Infrastructure Services (CIS) | P29: =IF(P$7<$AP$29,percPreTargetAdjustment,0%) -> 0 | Q29: =IF(Q$7<$AP$29,percPreTargetAdjustment,0%) -> 0 | R29: =IF(R$7<$AP$29,percPreTargetAdjustment,0%) -> 0 | S29: =IF(S$7<$AP$29,percPreTargetAdjustment,0%) -> 0 | T29: =IF(T$7<$AP$29,percPreTargetAdjustment,0%) -> 0 | U29: =IF(U$7<$AP$29,percPreTargetAdjustment,0%) -> 0 | V29: =IF(V$7<$AP$29,percPreTargetAdjustment,0%) -> 0 | W29: =IF(W$7<$AP$29,percPreTargetAdjustment,0%) -> 0 | ... AA29: =IF(AA$7<$AP$29,percPreTargetAdjustment,0%) -> 0 | AC29: =IF(AC$7<$AP$29,percPreTargetAdjustment,0%) -> 0 | AD29: =IF(AD$7<$AP$29,percPreTargetAdjustment,0%) -> 0 | AE29: =IF(AE$7<$AP$29,percPreTargetAdjustment,0%) -> 0 | AF29: =IF(AF$7<$AP$29,percPreTargetAdjustment,0%) -> 0 | AG29: =IF(AG$7<$AP$29,percPreTargetAdjustment,0%) -> 0 | AH29: =IF(AH$7<$AP$29,percPreTargetAdjustment,0%) -> 0 | AI29: =IF(AI$7<$AP$29,percPreTargetAdjustment,0%) -> 0 | AJ29: =IF(AJ$7<$AP$29,percPreTargetAdjustment,0%) -> 0 | ... AN29: =IF(AN$7<$AP$29,percPreTargetAdjustment,0%) -> 0 | AX29: =SUMIFS(AX30:AX38,$G30:$G38,"<>Option") -> 210944.85 | AY29: =SUMIFS(AY30:AY38,$G30:$G38,"<>Option") -> 347154.95 | AZ29: =SUMIFS(AZ30:AZ38,$G30:$G38,"<>Option") -> 297411.49 | BA29: =SUMIFS(BA30:BA38,$G30:$G38,"<>Option") -> 282540.91 | BB29: =SUMIFS(BB30:BB38,$G30:$G38,"<>Option") -> 268413.87 | BD29: =SUM(AX29:BB29) -> 1406466.1
C30: Cloud Center of Excellence – IT part | D30: Fixed monthly | E30: central | F30: n/a | I30: 18880.862 | J30: 18125.627 | K30: 17219.346 | L30: 16358.379 | M30: 15540.46 | O30: 1 | U30: =$O$30 -> 1 | V30: =$O$30 -> 1 | W30: =$O$30 -> 1 | X30: =$O$30 -> 1 | Y30: =$O$30 -> 1 | Z30: =$O$30 -> 1 | AA30: =$O$30 -> 1 | AC30: =$O$30 -> 1 | AD30: =$O$30 -> 1 | AE30: =$O$30 -> 1 | AF30: =$O$30 -> 1 | AG30: =$O$30 -> 1 | AH30: =$O$30 -> 1 | AI30: =$O$30 -> 1 | AJ30: =$O$30 -> 1 | ... AN30: =$O$30 -> 1 | AR30: =IFERROR(AVERAGE(P30:AA30),0) -> 1 | AS30: =IFERROR(AVERAGE(AC30:AN30),0) -> 1 | AT30: =O30 -> 1 | AU30: =AT30 -> 1 | AV30: =AU30 -> 1 | AX30: =P30*(I30*(100%+P$29))+Q30*(I30*(100%+Q$29))+R30*(I30*(100%+R$29))+S30*(I30*(100%+S$29))+T30*(I30*(100%+T$29))+U30*(I30*(100%+U$29))+V30*(I30*(100%+V$29))+W30*(I30*(100%+W$29))+X30*(I30*(100%+X$29))+Y30*(I30*(100%+Y$29))+Z30*(I30*(100%+Z$29))+AA30*(I30*(100%+AA$29)) -> 132166.03 | AY30: =AC30*(J30*(100%+AC$29))+AD30*(J30*(100%+AD$29))+AE30*(J30*(100%+AE$29))+AF30*(J30*(100%+AF$29))+AG30*(J30*(100%+AG$29))+AH30*(J30*(100%+AH$29))+AI30*(J30*(100%+AI$29))+AJ30*(J30*(100%+AJ$29))+AK30*(J30*(100%+AK$29))+AL30*(J30*(100%+AL$29))+AM30*(J30*(100%+AM$29))+AN30*(J30*(100%+AN$29)) -> 217507.53 | AZ30: =K30*AT30*AT$7 -> 206632.15 | BA30: =L30*AU30*AU$7 -> 196300.55 | BB30: =M30*AV30*AV$7 -> 186485.52 | BD30: =SUM(AX30:BB30) -> 939091.78
C31: Workload management
C32: Managed database non-PaaS | D32: Database Instance | E32: local | F32: wide | I32: 18.58313 | J32: 17.839805 | K32: 16.947815 | L32: 16.100424 | M32: 15.295403 | O32: 130 | U32: =$O$32 -> 130 | V32: =$O$32 -> 130 | W32: =$O$32 -> 130 | X32: =$O$32 -> 130 | Y32: =$O$32 -> 130 | Z32: =$O$32 -> 130 | AA32: =$O$32 -> 130 | AC32: =$O$32 -> 130 | AD32: =$O$32 -> 130 | AE32: =$O$32 -> 130 | AF32: =$O$32 -> 130 | AG32: =$O$32 -> 130 | AH32: =$O$32 -> 130 | AI32: =$O$32 -> 130 | AJ32: =$O$32 -> 130 | ... AN32: =$O$32 -> 130 | AR32: =IFERROR(AVERAGE(P32:AA32),0) -> 130 | AS32: =IFERROR(AVERAGE(AC32:AN32),0) -> 130 | AT32: =O32 -> 130 | AU32: =AT32 -> 130 | AV32: =AU32 -> 130 | AX32: =P32*(I32*(100%+P$29))+Q32*(I32*(100%+Q$29))+R32*(I32*(100%+R$29))+S32*(I32*(100%+S$29))+T32*(I32*(100%+T$29))+U32*(I32*(100%+U$29))+V32*(I32*(100%+V$29))+W32*(I32*(100%+W$29))+X32*(I32*(100%+X$29))+Y32*(I32*(100%+Y$29))+Z32*(I32*(100%+Z$29))+AA32*(I32*(100%+AA$29)) -> 16910.649 | AY32: =AC32*(J32*(100%+AC$29))+AD32*(J32*(100%+AD$29))+AE32*(J32*(100%+AE$29))+AF32*(J32*(100%+AF$29))+AG32*(J32*(100%+AG$29))+AH32*(J32*(100%+AH$29))+AI32*(J32*(100%+AI$29))+AJ32*(J32*(100%+AJ$29))+AK32*(J32*(100%+AK$29))+AL32*(J32*(100%+AL$29))+AM32*(J32*(100%+AM$29))+AN32*(J32*(100%+AN$29)) -> 27830.096 | AZ32: =K32*AT32*AT$7 -> 26438.591 | BA32: =L32*AU32*AU$7 -> 25116.662 | BB32: =M32*AV32*AV$7 -> 23860.829 | BD32: =SUM(AX32:BB32) -> 120156.83 | BF32: Baseline band is for all database instances combined | BG32: Database CMDB File: Infra Type "blank"
C33: Managed operating system (OS) – in Azure | D33: OS instance | E33: local | F33: normal | I33: 19.174621 | J33: 18.407636 | K33: 17.487255 | L33: 16.612892 | M33: 15.782247 | O33: 102 | U33: =$O$33 -> 102 | V33: =$O$33 -> 102 | W33: =$O$33 -> 102 | X33: =$O$33 -> 102 | Y33: =$O$33 -> 102 | Z33: =$O$33 -> 102 | AA33: =$O$33 -> 102 | AC33: =$O$33 -> 102 | AD33: =$O$33 -> 102 | AE33: =$O$33 -> 102 | AF33: =$O$33 -> 102 | AG33: =$O$33 -> 102 | AH33: =$O$33 -> 102 | AI33: =$O$33 -> 102 | AJ33: =$O$33 -> 102 | ... AN33: =$O$33 -> 102 | AR33: =IFERROR(AVERAGE(P33:AA33),0) -> 102 | AS33: =IFERROR(AVERAGE(AC33:AN33),0) -> 102 | AT33: =O33 -> 102 | AU33: =AT33 -> 102 | AV33: =AU33 -> 102 | AX33: =P33*(I33*(100%+P$29))+Q33*(I33*(100%+Q$29))+R33*(I33*(100%+R$29))+S33*(I33*(100%+S$29))+T33*(I33*(100%+T$29))+U33*(I33*(100%+U$29))+V33*(I33*(100%+V$29))+W33*(I33*(100%+W$29))+X33*(I33*(100%+X$29))+Y33*(I33*(100%+Y$29))+Z33*(I33*(100%+Z$29))+AA33*(I33*(100%+AA$29)) -> 13690.68 | AY33: =AC33*(J33*(100%+AC$29))+AD33*(J33*(100%+AD$29))+AE33*(J33*(100%+AE$29))+AF33*(J33*(100%+AF$29))+AG33*(J33*(100%+AG$29))+AH33*(J33*(100%+AH$29))+AI33*(J33*(100%+AI$29))+AJ33*(J33*(100%+AJ$29))+AK33*(J33*(100%+AK$29))+AL33*(J33*(100%+AL$29))+AM33*(J33*(100%+AM$29))+AN33*(J33*(100%+AN$29)) -> 22530.947 | AZ33: =K33*AT33*AT$7 -> 21404.4 | BA33: =L33*AU33*AU$7 -> 20334.18 | BB33: =M33*AV33*AV$7 -> 19317.471 | BD33: =SUM(AX33:BB33) -> 97277.676 | BF33: Baseline band is for all OS instances combined RDS Servers are due to be decommissioned but baseline maintained allowing for increased cloud adoption | BG33: 250228 Server CMDB File: Hosting location = "Cloud", ACN Server Function = "LAHS"&"RDS"
C34: Managed operating system (OS) – on premises | D34: OS instance | E34: local | F34: =$F$33 -> normal | I34: 16.918712 | J34: 16.241964 | K34: 15.429866 | L34: 14.658372 | M34: 13.925454 | O34: 22 | U34: =$O$34 -> 22 | V34: =$O$34 -> 22 | W34: =$O$34 -> 22 | X34: =$O$34 -> 22 | Y34: =$O$34 -> 22 | Z34: =$O$34 -> 22 | AA34: =$O$34 -> 22 | AC34: =$O$34 -> 22 | AD34: =$O$34 -> 22 | AE34: =$O$34 -> 22 | AF34: =$O$34 -> 22 | AG34: =$O$34 -> 22 | AH34: =$O$34 -> 22 | AI34: =$O$34 -> 22 | AJ34: =$O$34 -> 22 | ... AN34: =$O$34 -> 22 | AR34: =IFERROR(AVERAGE(P34:AA34),0) -> 22 | AS34: =IFERROR(AVERAGE(AC34:AN34),0) -> 22 | AT34: =O34 -> 22 | AU34: =AT34 -> 22 | AV34: =AU34 -> 22 | AX34: =P34*(I34*(100%+P$29))+Q34*(I34*(100%+Q$29))+R34*(I34*(100%+R$29))+S34*(I34*(100%+S$29))+T34*(I34*(100%+T$29))+U34*(I34*(100%+U$29))+V34*(I34*(100%+V$29))+W34*(I34*(100%+W$29))+X34*(I34*(100%+X$29))+Y34*(I34*(100%+Y$29))+Z34*(I34*(100%+Z$29))+AA34*(I34*(100%+AA$29)) -> 2605.4817 | AY34: =AC34*(J34*(100%+AC$29))+AD34*(J34*(100%+AD$29))+AE34*(J34*(100%+AE$29))+AF34*(J34*(100%+AF$29))+AG34*(J34*(100%+AG$29))+AH34*(J34*(100%+AH$29))+AI34*(J34*(100%+AI$29))+AJ34*(J34*(100%+AJ$29))+AK34*(J34*(100%+AK$29))+AL34*(J34*(100%+AL$29))+AM34*(J34*(100%+AM$29))+AN34*(J34*(100%+AN$29)) -> 4287.8784 | AZ34: =K34*AT34*AT$7 -> 4073.4845 | BA34: =L34*AU34*AU$7 -> 3869.8103 | BB34: =M34*AV34*AV$7 -> 3676.3198 | BD34: =SUM(AX34:BB34) -> 18512.975 | BF34: RDS Servers are due to be decommissioned however difference is minimal so baseline maintained. | BG34: Server CMDB File": Hosting Location = "On-Prem", Is Virtual = "Physical" & "Virtual" ("Yes"&"No"), ACN Server Function = "LAHS"&"RDS"
C35: On-premises server
C36: On-premises server – Service Management | D36: Physical Server | E36: local | F36: wide | I36: 39.269277 | J36: 37.698506 | K36: 35.813581 | L36: 34.022902 | M36: 32.321756 | O36: 55 | U36: =$O$36 -> 55 | V36: =$O$36 -> 55 | W36: =$O$36 -> 55 | X36: =$O$36 -> 55 | Y36: =$O$36 -> 55 | Z36: =$O$36 -> 55 | AA36: =$O$36 -> 55 | AC36: =$O$36 -> 55 | AD36: =$O$36 -> 55 | AE36: =$O$36 -> 55 | AF36: =$O$36 -> 55 | AG36: =$O$36 -> 55 | AH36: =$O$36 -> 55 | AI36: =$O$36 -> 55 | AJ36: =$O$36 -> 55 | ... AN36: =$O$36 -> 55 | AR36: =IFERROR(AVERAGE(P36:AA36),0) -> 55 | AS36: =IFERROR(AVERAGE(AC36:AN36),0) -> 55 | AT36: 30 | AU36: =AT36 -> 30 | AV36: =AU36 -> 30 | AX36: =P36*(I36*(100%+P$29))+Q36*(I36*(100%+Q$29))+R36*(I36*(100%+R$29))+S36*(I36*(100%+S$29))+T36*(I36*(100%+T$29))+U36*(I36*(100%+U$29))+V36*(I36*(100%+V$29))+W36*(I36*(100%+W$29))+X36*(I36*(100%+X$29))+Y36*(I36*(100%+Y$29))+Z36*(I36*(100%+Z$29))+AA36*(I36*(100%+AA$29)) -> 15118.672 | AY36: =AC36*(J36*(100%+AC$29))+AD36*(J36*(100%+AD$29))+AE36*(J36*(100%+AE$29))+AF36*(J36*(100%+AF$29))+AG36*(J36*(100%+AG$29))+AH36*(J36*(100%+AH$29))+AI36*(J36*(100%+AI$29))+AJ36*(J36*(100%+AJ$29))+AK36*(J36*(100%+AK$29))+AL36*(J36*(100%+AL$29))+AM36*(J36*(100%+AM$29))+AN36*(J36*(100%+AN$29)) -> 24881.014 | AZ36: =K36*AT36*AT$7 -> 12892.889 | BA36: =L36*AU36*AU$7 -> 12248.245 | BB36: =M36*AV36*AV$7 -> 11635.832 | BD36: =SUM(AX36:BB36) -> 76776.651 | BF36: Baseline band is for all Physical Servers combined | BG36: 250228 Server CMDB File: Server CMDB File: Hosting Location = "On-Prem", Is Virtual = "Physical" ("No"), ACN Server Function = "LAHS"&"RDS"&"EUS"
C37: On-premises server – Hardware Maintenance | D37: Physical Server | E37: local | F37: wide | I37: 79.099565 | J37: 75.935583 | K37: 72.138804 | L37: 68.531863 | M37: 65.10527 | O37: 55 | U37: =$O$37 -> 55 | V37: =$O$37 -> 55 | W37: =$O$37 -> 55 | X37: =$O$37 -> 55 | Y37: =$O$37 -> 55 | Z37: =$O$37 -> 55 | AA37: =$O$37 -> 55 | AC37: =$O$37 -> 55 | AD37: =$O$37 -> 55 | AE37: =$O$37 -> 55 | AF37: =$O$37 -> 55 | AG37: =$O$37 -> 55 | AH37: =$O$37 -> 55 | AI37: =$O$37 -> 55 | AJ37: =$O$37 -> 55 | ... AN37: =$O$37 -> 55 | AR37: =IFERROR(AVERAGE(P37:AA37),0) -> 55 | AS37: =IFERROR(AVERAGE(AC37:AN37),0) -> 55 | AT37: 30 | AU37: =AT37 -> 30 | AV37: =AU37 -> 30 | AX37: =P37*(I37*(100%+P$29))+Q37*(I37*(100%+Q$29))+R37*(I37*(100%+R$29))+S37*(I37*(100%+S$29))+T37*(I37*(100%+T$29))+U37*(I37*(100%+U$29))+V37*(I37*(100%+V$29))+W37*(I37*(100%+W$29))+X37*(I37*(100%+X$29))+Y37*(I37*(100%+Y$29))+Z37*(I37*(100%+Z$29))+AA37*(I37*(100%+AA$29)) -> 30453.333 | AY37: =AC37*(J37*(100%+AC$29))+AD37*(J37*(100%+AD$29))+AE37*(J37*(100%+AE$29))+AF37*(J37*(100%+AF$29))+AG37*(J37*(100%+AG$29))+AH37*(J37*(100%+AH$29))+AI37*(J37*(100%+AI$29))+AJ37*(J37*(100%+AJ$29))+AK37*(J37*(100%+AK$29))+AL37*(J37*(100%+AL$29))+AM37*(J37*(100%+AM$29))+AN37*(J37*(100%+AN$29)) -> 50117.485 | AZ37: =K37*AT37*AT$7 -> 25969.969 | BA37: =L37*AU37*AU$7 -> 24671.471 | BB37: =M37*AV37*AV$7 -> 23437.897 | BD37: =SUM(AX37:BB37) -> 154650.15 | BF37: Baseline band is for all Physical Servers combined
B39: Operational Technology Services (OTS) | P39: =IF(P$7<$AP$39,percPreTargetAdjustment,0%) -> 0 | Q39: =IF(Q$7<$AP$39,percPreTargetAdjustment,0%) -> 0 | R39: =IF(R$7<$AP$39,percPreTargetAdjustment,0%) -> 0 | S39: =IF(S$7<$AP$39,percPreTargetAdjustment,0%) -> 0 | T39: =IF(T$7<$AP$39,percPreTargetAdjustment,0%) -> 0 | U39: =IF(U$7<$AP$39,percPreTargetAdjustment,0%) -> 0 | V39: =IF(V$7<$AP$39,percPreTargetAdjustment,0%) -> 0 | W39: =IF(W$7<$AP$39,percPreTargetAdjustment,0%) -> 0 | ... AA39: =IF(AA$7<$AP$39,percPreTargetAdjustment,0%) -> 0 | AC39: =IF(AC$7<$AP$39,percPreTargetAdjustment,0%) -> 0 | AD39: =IF(AD$7<$AP$39,percPreTargetAdjustment,0%) -> 0 | AE39: =IF(AE$7<$AP$39,percPreTargetAdjustment,0%) -> 0 | AF39: =IF(AF$7<$AP$39,percPreTargetAdjustment,0%) -> 0 | AG39: =IF(AG$7<$AP$39,percPreTargetAdjustment,0%) -> 0 | AH39: =IF(AH$7<$AP$39,percPreTargetAdjustment,0%) -> 0 | AI39: =IF(AI$7<$AP$39,percPreTargetAdjustment,0%) -> 0 | AJ39: =IF(AJ$7<$AP$39,percPreTargetAdjustment,0%) -> 0 | ... AN39: =IF(AN$7<$AP$39,percPreTargetAdjustment,0%) -> 0 | AX39: =SUMIFS(AX40:AX57,$G40:$G57,"<>Option") -> 659134.54 | AY39: =SUMIFS(AY40:AY57,$G40:$G57,"<>Option") -> 1088781.9 | AZ39: =SUMIFS(AZ40:AZ57,$G40:$G57,"<>Option") -> 1034342.8 | BA39: =SUMIFS(BA40:BA57,$G40:$G57,"<>Option") -> 982625.63 | BB39: =SUMIFS(BB40:BB57,$G40:$G57,"<>Option") -> 933494.34 | BD39: =SUM(AX39:BB39) -> 4698379.1 | BF39: Music3 rollout assumed complete as of 1st of October 2025
C40: Cloud Center of Excellence – OT part | D40: Fixed monthly | E40: central | F40: n/a | I40: 10112.58 | J40: 9708.077 | K40: 9222.6732 | L40: 8761.5395 | M40: 8323.4625 | O40: 1 | U40: =$O$40 -> 1 | V40: =$AT40 -> 1 | W40: =$AT40 -> 1 | X40: =$AT40 -> 1 | Y40: =$AT40 -> 1 | Z40: =$AT40 -> 1 | AA40: =$AT40 -> 1 | AC40: =$AT40 -> 1 | AD40: =$AT40 -> 1 | AE40: =$AT40 -> 1 | AF40: =$AT40 -> 1 | AG40: =$AT40 -> 1 | AH40: =$AT40 -> 1 | AI40: =$AT40 -> 1 | AJ40: =$AT40 -> 1 | ... AN40: =$AT40 -> 1 | AR40: =IFERROR(AVERAGE(P40:AA40),0) -> 1 | AS40: =IFERROR(AVERAGE(AC40:AN40),0) -> 1 | AT40: =O40 -> 1 | AU40: =AT40 -> 1 | AV40: =AU40 -> 1 | AX40: =P40*(I40*(100%+P$39))+Q40*(I40*(100%+Q$39))+R40*(I40*(100%+R$39))+S40*(I40*(100%+S$39))+T40*(I40*(100%+T$39))+U40*(I40*(100%+U$39))+V40*(I40*(100%+V$39))+W40*(I40*(100%+W$39))+X40*(I40*(100%+X$39))+Y40*(I40*(100%+Y$39))+Z40*(I40*(100%+Z$39))+AA40*(I40*(100%+AA$39)) -> 70788.062 | AY40: =AC40*(J40*(100%+AC$39))+AD40*(J40*(100%+AD$39))+AE40*(J40*(100%+AE$39))+AF40*(J40*(100%+AF$39))+AG40*(J40*(100%+AG$39))+AH40*(J40*(100%+AH$39))+AI40*(J40*(100%+AI$39))+AJ40*(J40*(100%+AJ$39))+AK40*(J40*(100%+AK$39))+AL40*(J40*(100%+AL$39))+AM40*(J40*(100%+AM$39))+AN40*(J40*(100%+AN$39)) -> 116496.92 | AZ40: =K40*AT40*AT$7 -> 110672.08 | BA40: =L40*AU40*AU$7 -> 105138.47 | BB40: =M40*AV40*AV$7 -> 99881.55 | BD40: =SUM(AX40:BB40) -> 502977.09
C41: =C31 -> Workload management
C42: =C32 -> Managed database non-PaaS | D42: =D32 -> Database Instance | E42: =E32 -> local | F42: wide | I42: =I32 -> 18.58313 | J42: =J32 -> 17.839805 | K42: =K32 -> 16.947815 | L42: =L32 -> 16.100424 | M42: =M32 -> 15.295403 | O42: 86 | U42: =$O$42 -> 86 | V42: =$AT42 -> 101 | W42: =$AT42 -> 101 | X42: =$AT42 -> 101 | Y42: =$AT42 -> 101 | Z42: =$AT42 -> 101 | AA42: =$AT42 -> 101 | AC42: =$AT42 -> 101 | AD42: =$AT42 -> 101 | AE42: =$AT42 -> 101 | AF42: =$AT42 -> 101 | AG42: =$AT42 -> 101 | AH42: =$AT42 -> 101 | AI42: =$AT42 -> 101 | AJ42: =$AT42 -> 101 | ... AN42: =$AT42 -> 101 | AR42: =IFERROR(AVERAGE(P42:AA42),0) -> 98.857143 | AS42: =IFERROR(AVERAGE(AC42:AN42),0) -> 101 | AT42: =O42+15 -> 101 | AU42: =AT42 -> 101 | AV42: =AU42 -> 101 | AX42: =P42*(I42*(100%+P$29))+Q42*(I42*(100%+Q$29))+R42*(I42*(100%+R$29))+S42*(I42*(100%+S$29))+T42*(I42*(100%+T$29))+U42*(I42*(100%+U$29))+V42*(I42*(100%+V$29))+W42*(I42*(100%+W$29))+X42*(I42*(100%+X$29))+Y42*(I42*(100%+Y$29))+Z42*(I42*(100%+Z$29))+AA42*(I42*(100%+AA$29)) -> 12859.526 | AY42: =AC42*(J42*(100%+AC$29))+AD42*(J42*(100%+AD$29))+AE42*(J42*(100%+AE$29))+AF42*(J42*(100%+AF$29))+AG42*(J42*(100%+AG$29))+AH42*(J42*(100%+AH$29))+AI42*(J42*(100%+AI$29))+AJ42*(J42*(100%+AJ$29))+AK42*(J42*(100%+AK$29))+AL42*(J42*(100%+AL$29))+AM42*(J42*(100%+AM$29))+AN42*(J42*(100%+AN$29)) -> 21621.844 | AZ42: =K42*AT42*AT$7 -> 20540.752 | BA42: =L42*AU42*AU$7 -> 19513.714 | BB42: =M42*AV42*AV$7 -> 18538.028 | BD42: =SUM(AX42:BB42) -> 93073.865 | BF42: common for OTS workloads: Yr3 forecast based on MUSIC3: +15 assumed based on OT app servers listed in Managed operationing System (OS) - on premises. | BG42: Database CMDB File: Infra type "OT" Music3 is an ongoing OT Cyber Security project. The changes in volumes + & - will be introduced in phases between now and the end of September 2025 which is the current planned completion date of the project.
C43: =C33 -> Managed operating system (OS) – in Azure | D43: =D33 -> OS instance | E43: =E33 -> local | F43: =$F$33 -> normal | I43: =I33 -> 19.174621 | J43: =J33 -> 18.407636 | K43: =K33 -> 17.487255 | L43: =L33 -> 16.612892 | M43: =M33 -> 15.782247 | O43: 115 | U43: =$O$43 -> 115 | V43: =$AT43 -> 115 | W43: =$AT43 -> 115 | X43: =$AT43 -> 115 | Y43: =$AT43 -> 115 | Z43: =$AT43 -> 115 | AA43: =$AT43 -> 115 | AC43: =$AT43 -> 115 | AD43: =$AT43 -> 115 | AE43: =$AT43 -> 115 | AF43: =$AT43 -> 115 | AG43: =$AT43 -> 115 | AH43: =$AT43 -> 115 | AI43: =$AT43 -> 115 | AJ43: =$AT43 -> 115 | ... AN43: =$AT43 -> 115 | AR43: =IFERROR(AVERAGE(P43:AA43),0) -> 115 | AS43: =IFERROR(AVERAGE(AC43:AN43),0) -> 115 | AT43: =O43 -> 115 | AU43: =AT43 -> 115 | AV43: =AU43 -> 115 | AX43: =P43*(I43*(100%+P$29))+Q43*(I43*(100%+Q$29))+R43*(I43*(100%+R$29))+S43*(I43*(100%+S$29))+T43*(I43*(100%+T$29))+U43*(I43*(100%+U$29))+V43*(I43*(100%+V$29))+W43*(I43*(100%+W$29))+X43*(I43*(100%+X$29))+Y43*(I43*(100%+Y$29))+Z43*(I43*(100%+Z$29))+AA43*(I43*(100%+AA$29)) -> 15435.57 | AY43: =AC43*(J43*(100%+AC$29))+AD43*(J43*(100%+AD$29))+AE43*(J43*(100%+AE$29))+AF43*(J43*(100%+AF$29))+AG43*(J43*(100%+AG$29))+AH43*(J43*(100%+AH$29))+AI43*(J43*(100%+AI$29))+AJ43*(J43*(100%+AJ$29))+AK43*(J43*(100%+AK$29))+AL43*(J43*(100%+AL$29))+AM43*(J43*(100%+AM$29))+AN43*(J43*(100%+AN$29)) -> 25402.538 | AZ43: =K43*AT43*AT$7 -> 24132.411 | BA43: =L43*AU43*AU$7 -> 22925.791 | BB43: =M43*AV43*AV$7 -> 21779.501 | BD43: =SUM(AX43:BB43) -> 109675.81 | BF43: Baseline band is for all OS instances combined Compared to values from azure reporting there is a discrepancy of 18 servers. Azure values used, discrepancy to be investigated by JDE Assumptions for volume increase vs CMDB driving by Music3 program are in the 250228Server CMDB File | BG43: 250228Server CMDB File: Hosting Location = "Cloud", ACN Server Function = "MU-LAHS" &"MU-RAS"
C44: =C34 -> Managed operating system (OS) – on premises | D44: =D34 -> OS instance | E44: =E34 -> local | F44: =$F$33 -> normal | I44: =I34 -> 16.918712 | J44: =J34 -> 16.241964 | K44: =K34 -> 15.429866 | L44: =L34 -> 14.658372 | M44: =M34 -> 13.925454 | O44: 789 | U44: =$O$44 -> 789 | V44: =$AT44 -> 789 | W44: =$AT44 -> 789 | X44: =$AT44 -> 789 | Y44: =$AT44 -> 789 | Z44: =$AT44 -> 789 | AA44: =$AT44 -> 789 | AC44: =$AT44 -> 789 | AD44: =$AT44 -> 789 | AE44: =$AT44 -> 789 | AF44: =$AT44 -> 789 | AG44: =$AT44 -> 789 | AH44: =$AT44 -> 789 | AI44: =$AT44 -> 789 | AJ44: =$AT44 -> 789 | ... AN44: =$AT44 -> 789 | AR44: =IFERROR(AVERAGE(P44:AA44),0) -> 789 | AS44: =IFERROR(AVERAGE(AC44:AN44),0) -> 789 | AT44: 789 | AU44: =AT44 -> 789 | AV44: =AU44 -> 789 | AX44: =P44*(I44*(100%+P$29))+Q44*(I44*(100%+Q$29))+R44*(I44*(100%+R$29))+S44*(I44*(100%+S$29))+T44*(I44*(100%+T$29))+U44*(I44*(100%+U$29))+V44*(I44*(100%+V$29))+W44*(I44*(100%+W$29))+X44*(I44*(100%+X$29))+Y44*(I44*(100%+Y$29))+Z44*(I44*(100%+Z$29))+AA44*(I44*(100%+AA$29)) -> 93442.048 | AY44: =AC44*(J44*(100%+AC$29))+AD44*(J44*(100%+AD$29))+AE44*(J44*(100%+AE$29))+AF44*(J44*(100%+AF$29))+AG44*(J44*(100%+AG$29))+AH44*(J44*(100%+AH$29))+AI44*(J44*(100%+AI$29))+AJ44*(J44*(100%+AJ$29))+AK44*(J44*(100%+AK$29))+AL44*(J44*(100%+AL$29))+AM44*(J44*(100%+AM$29))+AN44*(J44*(100%+AN$29)) -> 153778.91 | AZ44: =K44*AT44*AT$7 -> 146089.97 | BA44: =L44*AU44*AU$7 -> 138785.47 | BB44: =M44*AV44*AV$7 -> 131846.2 | BD44: =SUM(AX44:BB44) -> 663942.59 | BF44: Assumptions for volume increase vs CMDB driving by Music3 program are in the 250228Server CMDB File | BG44: 250228Server CMDB File: Hosting Location = "On-Prem", Is Virtual = "Virtual"&"Physical" ("Yes"& "No"), ACN Server Function = "MU-LAHS"&"MU-RAS"
...

Sheet RU info
A1: Schedule 5.A (Pricing Sheet) – Resource Unit information
B4: Default Unit measurements for Monthly Recurring Charges
C5: The following common definitions apply to describe default (standard) Units and Unit measurements as used in the Unit Price section below. Each Unit is measured as set out in Schedule 5.B (Charges) for that month, based on information in Customer’s ITSM Tooling – which may originate from other systems.
B6: Unit Measurement | C6: Definition of measuring
B7: Fixed monthly | C7: Single Price for a complete or part of a Service Component, including any underpinning Service Components.
B8: User | C8: The number of Users ('named') which: • are Personnel, excluding Personnel of Supplier and Supplier Third Parties • are authorized to use the respective Service (such as SDS or AVD), and • are active in Customer's authoritative source ('lastSignInDateTime' is in the last 60 Days). Authorization is maintained in the user account directory and synchronized with the ITSM Tooling where it is reported from.
B9: PC device | C9: A personal computer class of device that: • runs an agreed workplace operating system, and • is assigned to one or more Users, and • is in the ‘Monitor and Service’ stage set out in Schedule 3.B3 (Asset Lifecycle Services) – meaning for example not being provisioned, in stock, or retired.
B10: Mobile Device | C10: A smartphone or tablet computer class of device that: • runs an agreed operating system for the mobile world, such as Apple iOS, iPadOS, or Google Android (variations), and • is assigned to one or more Users, and • is in the ‘Monitor and Service’ stage set out in Schedule 3.B3 (Asset Lifecycle Services) – meaning for example not being provisioned, in stock, or retired.
B11: Meeting room | C11: A physical room at a Customer Location with the required audiovisual equipment active in Customer's Microsoft Teams environment.
B12: Physical Server | C12: Is an independent, functional, physical compute host: • physically located in a Customer Location (on-premises), and is typically used to run one or more virtual OS instances, and • is in the ‘Monitor and Service’ stage set out in Schedule 3.B2 (Asset Lifecycle Responsibilities). This number is measured and reported using the IT Service Management Tool
B13: Database Instance | C13: The number of databases instances (this includes all databases of the instance). This number is measured and reported using the ITSM Tooling, based on input from for example the public cloud ‘update manager / subscriptions / tagging’ in. One counted database instance can ‘serve’ one or more Applications, and vice versa one Application can ‘use’ one or more databases. For the avoidance of doubt: Platform-as-a-Service (PaaS, using NIST definition) databases are not counted as databases.
